Count,Message,Traceback,Nodes
4,"HTTPConnectionPool(host='10.28.45.81', port=8080): Max retries exceeded with url: /postservice/categories (Caused by NewConnectionError('<urllib3.connection.HTTPConnection object at 0x7febfdc26fd0>: Failed to establish a new connection: [Errno 111] Connection refused'))","  File ""/opt/venv/lib/python3.11/site-packages/locust/user/task.py"", line 340, in run
    self.execute_next_task()
  File ""/opt/venv/lib/python3.11/site-packages/locust/user/task.py"", line 373, in execute_next_task
    self.execute_task(self._task_queue.popleft())
  File ""/opt/venv/lib/python3.11/site-packages/locust/user/task.py"", line 385, in execute_task
    task(self)
  File ""/mnt/locust/common/postservice.py"", line 104, in get_categories
    self.get_categories_paginated(0)
  File ""/mnt/locust/common/postservice.py"", line 110, in get_categories_paginated
    if not response.ok:
           ^^^^^^^^^^^
  File ""/opt/venv/lib/python3.11/site-packages/requests/models.py"", line 764, in ok
    self.raise_for_status()
  File ""/opt/venv/lib/python3.11/site-packages/locust/clients.py"", line 61, in raise_for_status
    raise self.error
  File ""/opt/venv/lib/python3.11/site-packages/locust/clients.py"", line 237, in _send_request_safe_mode
    return super().request(method, url, **kwargs)
           ^^^^^^^^^^^^^^^^^^^^^^^^^^^^^^^^^^^^^^
  File ""/opt/venv/lib/python3.11/site-packages/requests/sessions.py"", line 589, in request
    resp = self.send(prep, **send_kwargs)
           ^^^^^^^^^^^^^^^^^^^^^^^^^^^^^^
  File ""/opt/venv/lib/python3.11/site-packages/requests/sessions.py"", line 703, in send
    r = adapter.send(request, **kwargs)
        ^^^^^^^^^^^^^^^^^^^^^^^^^^^^^^^
  File ""/opt/venv/lib/python3.11/site-packages/requests/adapters.py"", line 700, in send
    raise ConnectionError(e, request=request)
","15eb723a77b8_953a498a58544976aeee068b1790c661, bb48c8bfd58e_013e5e223f53423dba5f9369c6e6dcea, 2ad7a0d501df_f809d804cf14429d9ab0f4089fb890b6, 3182be9bc20e_30e877ed1b03497eb2a68b09e09749a8"
3,"HTTPConnectionPool(host='10.28.45.81', port=8080): Max retries exceeded with url: /userservice/users/search?page=0&query=%25RWBj (Caused by NewConnectionError('<urllib3.connection.HTTPConnection object at 0x7ffb41edb7d0>: Failed to establish a new connection: [Errno 111] Connection refused'))","  File ""/opt/venv/lib/python3.11/site-packages/locust/user/task.py"", line 340, in run
    self.execute_next_task()
  File ""/opt/venv/lib/python3.11/site-packages/locust/user/task.py"", line 373, in execute_next_task
    self.execute_task(self._task_queue.popleft())
  File ""/opt/venv/lib/python3.11/site-packages/locust/user/task.py"", line 385, in execute_task
    task(self)
  File ""/mnt/locust/common/userservice.py"", line 83, in search_user
    self.search_user_paginated(letters, 0)
  File ""/mnt/locust/common/userservice.py"", line 89, in search_user_paginated
    if not response.ok:
           ^^^^^^^^^^^
  File ""/opt/venv/lib/python3.11/site-packages/requests/models.py"", line 764, in ok
    self.raise_for_status()
  File ""/opt/venv/lib/python3.11/site-packages/locust/clients.py"", line 61, in raise_for_status
    raise self.error
  File ""/opt/venv/lib/python3.11/site-packages/locust/clients.py"", line 237, in _send_request_safe_mode
    return super().request(method, url, **kwargs)
           ^^^^^^^^^^^^^^^^^^^^^^^^^^^^^^^^^^^^^^
  File ""/opt/venv/lib/python3.11/site-packages/requests/sessions.py"", line 589, in request
    resp = self.send(prep, **send_kwargs)
           ^^^^^^^^^^^^^^^^^^^^^^^^^^^^^^
  File ""/opt/venv/lib/python3.11/site-packages/requests/sessions.py"", line 703, in send
    r = adapter.send(request, **kwargs)
        ^^^^^^^^^^^^^^^^^^^^^^^^^^^^^^^
  File ""/opt/venv/lib/python3.11/site-packages/requests/adapters.py"", line 700, in send
    raise ConnectionError(e, request=request)
","15eb723a77b8_953a498a58544976aeee068b1790c661, 3182be9bc20e_30e877ed1b03497eb2a68b09e09749a8, dac7ad47465d_5a8b6c93423d40b49a4c34fd78de6f0e"
2,"HTTPConnectionPool(host='10.28.45.81', port=8080): Max retries exceeded with url: /postservice/posts?category=None (Caused by NewConnectionError('<urllib3.connection.HTTPConnection object at 0x7f331a1cf110>: Failed to establish a new connection: [Errno 111] Connection refused'))","  File ""/opt/venv/lib/python3.11/site-packages/locust/user/task.py"", line 340, in run
    self.execute_next_task()
  File ""/opt/venv/lib/python3.11/site-packages/locust/user/task.py"", line 373, in execute_next_task
    self.execute_task(self._task_queue.popleft())
  File ""/opt/venv/lib/python3.11/site-packages/locust/user/task.py"", line 385, in execute_task
    task(self)
  File ""/mnt/locust/common/postservice.py"", line 129, in get_posts
    self.get_posts_paginated_filtered(0, category=category, user_id=user_id)
  File ""/mnt/locust/common/postservice.py"", line 140, in get_posts_paginated_filtered
    if not response.ok:
           ^^^^^^^^^^^
  File ""/opt/venv/lib/python3.11/site-packages/requests/models.py"", line 764, in ok
    self.raise_for_status()
  File ""/opt/venv/lib/python3.11/site-packages/locust/clients.py"", line 61, in raise_for_status
    raise self.error
  File ""/opt/venv/lib/python3.11/site-packages/locust/clients.py"", line 237, in _send_request_safe_mode
    return super().request(method, url, **kwargs)
           ^^^^^^^^^^^^^^^^^^^^^^^^^^^^^^^^^^^^^^
  File ""/opt/venv/lib/python3.11/site-packages/requests/sessions.py"", line 589, in request
    resp = self.send(prep, **send_kwargs)
           ^^^^^^^^^^^^^^^^^^^^^^^^^^^^^^
  File ""/opt/venv/lib/python3.11/site-packages/requests/sessions.py"", line 703, in send
    r = adapter.send(request, **kwargs)
        ^^^^^^^^^^^^^^^^^^^^^^^^^^^^^^^
  File ""/opt/venv/lib/python3.11/site-packages/requests/adapters.py"", line 700, in send
    raise ConnectionError(e, request=request)
","d3fec85fa459_521c41be5ae840dda1a75d9f92815c70, 08b9501be1b7_1f41ccdbab41442faf1c78562624efca"
